<mujoco model="GRMini1T2"><compiler angle="radian" autolimits="true"/><asset><material name="default_material" rgba="0.7 0.7 0.7 1"/><mesh name="right_end_effector_link.STL" file="../meshes/right_end_effector_link.STL"/><mesh name="right_upper_arm_yaw_link.STL" file="../meshes/right_upper_arm_yaw_link.STL"/><mesh name="right_upper_arm_roll_link.STL" file="../meshes/right_upper_arm_roll_link.STL"/><mesh name="left_end_effector_link.STL" file="../meshes/left_end_effector_link.STL"/><mesh name="left_lower_arm_pitch_link.STL" file="../meshes/left_lower_arm_pitch_link.STL"/><mesh name="right_upper_arm_pitch_link.STL" file="../meshes/right_upper_arm_pitch_link.STL"/><mesh name="left_upper_arm_yaw_link.STL" file="../meshes/left_upper_arm_yaw_link.STL"/><mesh name="left_upper_arm_pitch_link.STL" file="../meshes/left_upper_arm_pitch_link.STL"/><mesh name="torso_link.STL" file="../meshes/torso_link.STL"/><mesh name="waist_yaw_link.STL" file="../meshes/waist_yaw_link.STL"/><mesh name="imu_link.STL" file="../meshes/imu_link.STL"/><mesh name="right_foot_pitch_link.STL" file="../meshes/right_foot_pitch_link.STL"/><mesh name="left_thigh_pitch_link.STL" file="../meshes/left_thigh_pitch_link.STL"/><mesh name="right_thigh_roll_link.STL" file="../meshes/right_thigh_roll_link.STL"/><mesh name="right_thigh_yaw_link.STL" file="../meshes/right_thigh_yaw_link.STL"/><mesh name="left_hand_yaw_link.STL" file="../meshes/left_hand_yaw_link.STL"/><mesh name="left_thigh_yaw_link.STL" file="../meshes/left_thigh_yaw_link.STL"/><mesh name="left_shank_pitch_link.STL" file="../meshes/left_shank_pitch_link.STL"/><mesh name="right_hand_yaw_link.STL" file="../meshes/right_hand_yaw_link.STL"/><mesh name="right_lower_arm_pitch_link.STL" file="../meshes/right_lower_arm_pitch_link.STL"/><mesh name="left_foot_roll_link.STL" file="../meshes/left_foot_roll_link.STL"/><mesh name="left_upper_arm_roll_link.STL" file="../meshes/left_upper_arm_roll_link.STL"/><mesh name="camera_link.STL" file="../meshes/camera_link.STL"/><mesh name="base_link.STL" file="../meshes/base_link.STL"/><mesh name="left_foot_pitch_link.STL" file="../meshes/left_foot_pitch_link.STL"/><mesh name="right_shank_pitch_link.STL" file="../meshes/right_shank_pitch_link.STL"/><mesh name="right_thigh_pitch_link.STL" file="../meshes/right_thigh_pitch_link.STL"/><mesh name="left_thigh_roll_link.STL" file="../meshes/left_thigh_roll_link.STL"/><mesh name="right_foot_roll_link.STL" file="../meshes/right_foot_roll_link.STL"/></asset><default><default class="visual"><geom group="2" contype="0" conaffinity="0"/></default><default class="collision"><geom group="3" mass="0" density="0"/></default></default><worldbody><light name="key_light" mode="targetbody" target="base_link" pos="3 -3 4" diffuse="0.95 0.95 0.95" specular="0.2 0.2 0.2"/><light name="fill_light" directional="true" dir="-0.2 -0.1 -1" diffuse="0.35 0.35 0.35" specular="0.08 0.08 0.08"/><geom name="floor" type="plane" size="0 0 0.05" rgba="0.2 0.3 0.4 1"/><body name="base_link" pos="0 0 0" quat="1 0 0 0"><freejoint name="base_free_joint"/><inertial pos="0.00025493 1.049e-05 -0.055019999999999999" quat="1 0 0 0" mass="3.1800000000000002" diaginertia="0.011139 0.0076189999999999999 0.0089904000000000008"/><geom name="base_link_collision" class="collision" type="cylinder" pos="0 0 -0.050000000000000003" quat="0.70738826916719977 0.70682518110536596 0 0" size="0.065000000000000002 0.067500000000000004"/><geom name="base_link_visual" class="visual" type="mesh" material="default_material" pos="0 0 0" quat="1 0 0 0" mesh="base_link.STL"/><body name="imu_link" pos="0 0 -0.1472" quat="1 0 0 0"><inertial pos="-0.0071124999999999999 0 0.00072935999999999997" quat="1 0 0 0" mass="0.037999999999999999" diaginertia="8.6899999999999998e-06 2.012e-05 2.336e-05"/><geom name="imu_link_visual" class="visual" type="mesh" material="default_material" pos="0 0 0" quat="1 0 0 0" mesh="imu_link.STL"/></body><body name="left_thigh_pitch_link" pos="0 0.050452999999999998 -0.067364999999999994" quat="0.99144482141964096 -0.13052649570173921 0 0"><joint name="left_hip_pitch_joint" type="hinge" axis="0 1 0" range="-2.617 2.617"/><inertial pos="-0.017114000000000001 0.035513999999999997 0.00025368" quat="1 0 0 0" mass="1.3100000000000001" diaginertia="0.12319793999999999 0.12353984 0.12463263999999999"/><geom name="left_thigh_pitch_link_visual" class="visual" type="mesh" material="default_material" pos="0 0 0" quat="1 0 0 0" mesh="left_thigh_pitch_link.STL"/><body name="left_thigh_roll_link" pos="0 0.071999999999999995 0" quat="0.99144482141964096 0.13052649570173921 0 0"><joint name="left_hip_roll_joint" type="hinge" axis="1 0 0" range="-0.26100000000000001 1.5700000000000001"/><inertial pos="-0.0029103000000000002 -4.9200000000000003e-06 -0.020022999999999999" quat="1 0 0 0" mass="1.3500000000000001" diaginertia="0.16948140913930801 0.169418509139308 0.16889950913930799"/><geom name="left_thigh_roll_link_collision" class="collision" type="cylinder" pos="0 0 0" quat="0.7073882691671548 0 0.70682518110541082 0" size="0.041500000000000002 0.040000000000000001"/><geom name="left_thigh_roll_link_visual" class="visual" type="mesh" material="default_material" pos="0 0 0" quat="1 0 0 0" mesh="left_thigh_roll_link.STL"/><body name="left_thigh_yaw_link" pos="0 0 -0.081500000000000003" quat="1 0 0 0"><joint name="left_hip_yaw_joint" type="hinge" axis="0 0 1" range="-2.617 2.617"/><inertial pos="0.0021440999999999999 -0.010607999999999999 -0.086615999999999999" quat="1 0 0 0" mass="3.3700000000000001" diaginertia="0.18234200913930798 0.182416009139308 0.172899009139308"/><geom name="left_thigh_yaw_link_collision" class="collision" type="cylinder" pos="0 0 -0.080000000000000002" quat="1 0 0 0" size="0.059999999999999998 0.095000000000000001"/><geom name="left_thigh_yaw_link_visual" class="visual" type="mesh" material="default_material" pos="0 0 0" quat="1 0 0 0" mesh="left_thigh_yaw_link.STL"/><body name="left_shank_pitch_link" pos="0 0 -0.20749999999999999" quat="1 0 0 0"><joint name="left_knee_pitch_joint" type="hinge" axis="0 1 0" range="-0.0872 2.3559999999999999"/><inertial pos="0.0027736000000000002 0.0049963999999999998 -0.13547000000000001" quat="1 0 0 0" mass="2.21" diaginertia="0.13462723999999998 0.13466323999999999 0.12272263999999999"/><geom name="left_shank_pitch_link_collision" class="collision" type="cylinder" pos="0 0 -0.12" quat="1 0 0 0" size="0.040000000000000001 0.10000000000000001"/><geom name="left_shank_pitch_link_visual" class="visual" type="mesh" material="default_material" pos="0 0 0" quat="1 0 0 0" mesh="left_shank_pitch_link.STL"/><body name="left_foot_roll_link" pos="0 0 -0.28000000000000003" quat="1 0 0 0"><joint name="left_ankle_roll_joint" type="hinge" axis="1 0 0" range="-0.436 0.436"/><inertial pos="0 0.0018625 0" quat="1 0 0 0" mass="0.113" diaginertia="0.031307100000000004 0.031293950000000001 0.031311470000000001"/><geom name="left_foot_roll_link_visual" class="visual" type="mesh" material="default_material" pos="0 0 0" quat="1 0 0 0" mesh="left_foot_roll_link.STL"/><body name="left_foot_pitch_link" pos="0 0 0" quat="1 0 0 0"><joint name="left_ankle_pitch_joint" type="hinge" axis="0 1 0" range="-0.436 0.436"/><inertial pos="0.031083 -0.00011033 -0.031858999999999998" quat="1 0 0 0" mass="0.52800000000000002" diaginertia="0.031535920000000002 0.032962600000000002 0.033114600000000001"/><geom name="left_foot_pitch_link_collision_0" class="collision" type="cylinder" pos="0.033000000000000002 0 -0.035000000000000003" quat="0.70714083703143737 0 0.70707272370137297 0" size="0.012500000000000001 0.089999999999999997"/><geom name="left_foot_pitch_link_collision_1" class="collision" type="cylinder" pos="0.033000000000000002 0.025000000000000001 -0.035000000000000003" quat="0.70714083703143737 0 0.70707272370137297 0" size="0.012500000000000001 0.089999999999999997"/><geom name="left_foot_pitch_link_collision_2" class="collision" type="cylinder" pos="0.033000000000000002 -0.025000000000000001 -0.035000000000000003" quat="0.70714083703143737 0 0.70707272370137297 0" size="0.012500000000000001 0.089999999999999997"/><geom name="left_foot_pitch_link_visual" class="visual" type="mesh" material="default_material" pos="0 0 0" quat="1 0 0 0" mesh="left_foot_pitch_link.STL"/></body></body></body></body></body></body><body name="right_thigh_pitch_link" pos="0 -0.050452999999999998 -0.067364999999999994" quat="0.99144482141964096 0.13052649570173921 0 0"><joint name="right_hip_pitch_joint" type="hinge" axis="0 1 0" range="-2.617 2.617"/><inertial pos="-0.017114000000000001 -0.035514999999999998 0.00025329999999999998" quat="1 0 0 0" mass="1.3100000000000001" diaginertia="0.12319793999999999 0.12353984 0.12463244"/><geom name="right_thigh_pitch_link_visual" class="visual" type="mesh" material="default_material" pos="0 0 0" quat="1 0 0 0" mesh="right_thigh_pitch_link.STL"/><body name="right_thigh_roll_link" pos="0 -0.071999999999999995 0" quat="0.99144482141964096 -0.13052649570173921 0 0"><joint name="right_hip_roll_joint" type="hinge" axis="1 0 0" range="-1.5700000000000001 0.26100000000000001"/><inertial pos="-0.0029091999999999998 1.208e-05 -0.020022999999999999" quat="1 0 0 0" mass="1.3500000000000001" diaginertia="0.16948130913930801 0.16941860913930801 0.16889950913930799"/><geom name="right_thigh_roll_link_collision" class="collision" type="cylinder" pos="0 0 0" quat="0.7073882691671548 0 0.70682518110541082 0" size="0.041500000000000002 0.040000000000000001"/><geom name="right_thigh_roll_link_visual" class="visual" type="mesh" material="default_material" pos="0 0 0" quat="1 0 0 0" mesh="right_thigh_roll_link.STL"/><body name="right_thigh_yaw_link" pos="0 0 -0.081500000000000003" quat="1 0 0 0"><joint name="right_hip_yaw_joint" type="hinge" axis="0 0 1" range="-2.617 2.617"/><inertial pos="0.0020430000000000001 0.010083 -0.086622000000000005" quat="1 0 0 0" mass="3.3700000000000001" diaginertia="0.182417009139308 0.182474009139308 0.17290400913930801"/><geom name="right_thigh_yaw_link_collision" class="collision" type="cylinder" pos="0 0 -0.080000000000000002" quat="1 0 0 0" size="0.059999999999999998 0.095000000000000001"/><geom name="right_thigh_yaw_link_visual" class="visual" type="mesh" material="default_material" pos="0 0 0" quat="1 0 0 0" mesh="right_thigh_yaw_link.STL"/><body name="right_shank_pitch_link" pos="0 0 -0.20749999999999999" quat="1 0 0 0"><joint name="right_knee_pitch_joint" type="hinge" axis="0 1 0" range="-0.0872 2.3559999999999999"/><inertial pos="0.0026916000000000002 -0.0047840000000000001 -0.13593" quat="1 0 0 0" mass="2.21" diaginertia="0.13445424 0.13448124 0.12274104"/><geom name="right_shank_pitch_link_collision" class="collision" type="cylinder" pos="0 0 -0.12" quat="1 0 0 0" size="0.040000000000000001 0.10000000000000001"/><geom name="right_shank_pitch_link_visual" class="visual" type="mesh" material="default_material" pos="0 0 0" quat="1 0 0 0" mesh="right_shank_pitch_link.STL"/><body name="right_foot_roll_link" pos="0 0 -0.28000000000000003" quat="1 0 0 0"><joint name="right_ankle_roll_joint" type="hinge" axis="1 0 0" range="-0.436 0.436"/><inertial pos="0 -0.0018793 0" quat="1 0 0 0" mass="0.113" diaginertia="0.031307170000000002 0.031293950000000001 0.031311530000000004"/><geom name="right_foot_roll_link_visual" class="visual" type="mesh" material="default_material" pos="0 0 0" quat="1 0 0 0" mesh="right_foot_roll_link.STL"/><body name="right_foot_pitch_link" pos="0 0 0" quat="1 0 0 0"><joint name="right_ankle_pitch_joint" type="hinge" axis="0 1 0" range="-0.436 0.436"/><inertial pos="0.031081999999999999 0.00015770000000000001 -0.031593000000000003" quat="1 0 0 0" mass="0.52800000000000002" diaginertia="0.03153591 0.032962500000000006 0.033114600000000001"/><geom name="right_foot_pitch_link_collision_0" class="collision" type="cylinder" pos="0.033000000000000002 0 -0.035000000000000003" quat="0.70714083703143737 0 0.70707272370137297 0" size="0.012500000000000001 0.089999999999999997"/><geom name="right_foot_pitch_link_collision_1" class="collision" type="cylinder" pos="0.033000000000000002 0.025000000000000001 -0.035000000000000003" quat="0.70714083703143737 0 0.70707272370137297 0" size="0.012500000000000001 0.089999999999999997"/><geom name="right_foot_pitch_link_collision_2" class="collision" type="cylinder" pos="0.033000000000000002 -0.025000000000000001 -0.035000000000000003" quat="0.70714083703143737 0 0.70707272370137297 0" size="0.012500000000000001 0.089999999999999997"/><geom name="right_foot_pitch_link_visual" class="visual" type="mesh" material="default_material" pos="0 0 0" quat="1 0 0 0" mesh="right_foot_pitch_link.STL"/></body></body></body></body></body></body><body name="waist_yaw_link" pos="0 0 0.025600000000000001" quat="1 0 0 0"><joint name="waist_yaw_joint" type="hinge" axis="0 0 1" range="-2.617 2.617"/><inertial pos="0.00025493 1.049e-05 -0.055019999999999999" quat="1 0 0 0" mass="3.1800000000000002" diaginertia="0.17873100913930801 0.17521100913930798 0.17658240913930801"/><geom name="waist_yaw_link_collision" class="collision" type="cylinder" pos="0 0 0.040000000000000001" quat="1 0 0 0" size="0.059999999999999998 0.0275"/><geom name="waist_yaw_link_visual" class="visual" type="mesh" material="default_material" pos="0 0 0" quat="1 0 0 0" mesh="waist_yaw_link.STL"/><body name="torso_link" pos="0 0 0.25979999999999998" quat="1 0 0 0"><inertial pos="0.0070826999999999999 0.00038627000000000003 -0.041746999999999999" quat="1 0 0 0" mass="7.9900000000000002" diaginertia="0.081894999999999996 0.070788000000000004 0.035401000000000002"/><geom name="torso_link_collision_0" class="collision" type="cylinder" pos="0 0 -0.059999999999999998" quat="1 0 0 0" size="0.10000000000000001 0.074999999999999997"/><geom name="torso_link_collision_1" class="collision" type="sphere" pos="0 0 0.19" quat="1 0 0 0" size="0.080000000000000002"/><geom name="torso_link_visual" class="visual" type="mesh" material="default_material" pos="0 0 0" quat="1 0 0 0" mesh="torso_link.STL"/><body name="camera_link" pos="0.071343000000000004 -0.0048076999999999998 0.17959" quat="0.96537906096875514 0.0087059558648255823 0.25867317321479294 -0.032490990051921284"><inertial pos="0.011771999999999999 0.0016608 2.48e-06" quat="1 0 0 0" mass="0.038199999999999998" diaginertia="2.4660000000000001e-05 3.6600000000000001e-06 2.4830000000000001e-05"/><geom name="camera_link_visual" class="visual" type="mesh" material="default_material" pos="0 0 0" quat="1 0 0 0" mesh="camera_link.STL"/></body><body name="left_upper_arm_pitch_link" pos="0 0.097650000000000001 0" quat="1 0 0 0"><joint name="left_shoulder_pitch_joint" type="hinge" axis="0 1 0" range="-2.9660000000000002 2.9660000000000002"/><inertial pos="-0.00045951999999999999 0.060859000000000003 7.7299999999999995e-05" quat="1 0 0 0" mass="0.88500000000000001" diaginertia="0.16842761913930798 0.16811168913930799 0.16840614913930799"/><geom name="left_upper_arm_pitch_link_visual" class="visual" type="mesh" material="default_material" pos="0 0 0" quat="1 0 0 0" mesh="left_upper_arm_pitch_link.STL"/><body name="left_upper_arm_roll_link" pos="0 0.078 0" quat="1 0 0 0"><joint name="left_shoulder_roll_joint" type="hinge" axis="1 0 0" range="-0.17399999999999999 2.7919999999999998"/><inertial pos="0.0049528999999999997 0.00053147999999999997 -0.043368999999999998" quat="1 0 0 0" mass="0.71599999999999997" diaginertia="0.033068600000000004 0.033179200000000006 0.031772070000000006"/><geom name="left_upper_arm_roll_link_collision" class="collision" type="sphere" pos="0 0 0" quat="1 0 0 0" size="0.032000000000000001"/><geom name="left_upper_arm_roll_link_visual" class="visual" type="mesh" material="default_material" pos="0 0 0" quat="1 0 0 0" mesh="left_upper_arm_roll_link.STL"/><body name="left_upper_arm_yaw_link" pos="0 0 -0.10050000000000001" quat="1 0 0 0"><joint name="left_shoulder_yaw_joint" type="hinge" axis="0 0 1" range="-1.8320000000000001 1.8320000000000001"/><inertial pos="0 -0.00057868999999999998 -0.060728999999999998" quat="1 0 0 0" mass="0.91300000000000003" diaginertia="0.034177600000000002 0.034195500000000004 0.031887450000000005"/><geom name="left_upper_arm_yaw_link_collision" class="collision" type="cylinder" pos="0 0 0" quat="1 0 0 0" size="0.032000000000000001 0.059999999999999998"/><geom name="left_upper_arm_yaw_link_visual" class="visual" type="mesh" material="default_material" pos="0 0 0" quat="1 0 0 0" mesh="left_upper_arm_yaw_link.STL"/><body name="left_lower_arm_pitch_link" pos="0 0 -0.1095" quat="-0.70710548251688432 8.6595605623403291e-17 0.70710807985382562 8.6595605623403291e-17"><joint name="left_elbow_pitch_joint" type="hinge" axis="0 1 0" range="-0.34899999999999998 1.6579999999999999"/><inertial pos="-0.00053164 0.0049499000000000001 -0.043369999999999999" quat="1 0 0 0" mass="0.71599999999999997" diaginertia="0.033178800000000001 0.033068300000000002 0.031771960000000002"/><geom name="left_lower_arm_pitch_link_visual" class="visual" type="mesh" material="default_material" pos="0 0 0" quat="1 0 0 0" mesh="left_lower_arm_pitch_link.STL"/><body name="left_hand_yaw_link" pos="0 0 -0.10050000000000001" quat="1 0 0 0"><joint name="left_wrist_yaw_joint" type="hinge" axis="0 0 1" range="-1.8320000000000001 1.8320000000000001"/><inertial pos="-0.0020834999999999998 6.3860000000000002e-05 -0.013715" quat="1 0 0 0" mass="0.44" diaginertia="0.031715740000000006 0.031689800000000004 0.03155227"/><geom name="left_hand_yaw_link_collision" class="collision" type="cylinder" pos="0 0 0" quat="1 0 0 0" size="0.032000000000000001 0.059999999999999998"/><geom name="left_hand_yaw_link_visual" class="visual" type="mesh" material="default_material" pos="0 0 0" quat="1 0 0 0" mesh="left_hand_yaw_link.STL"/><body name="left_end_effector_link" pos="0 0 -0.1045" quat="1 0 0 0"><inertial pos="0.0034650000000000002 0 0" quat="1 0 0 0" mass="0.099400000000000002" diaginertia="3.7410000000000003e-05 3.7410000000000003e-05 4.5380000000000003e-05"/><geom name="left_end_effector_link_collision" class="collision" type="sphere" pos="0 0 0" quat="1 0 0 0" size="0.02751"/><geom name="left_end_effector_link_visual" class="visual" type="mesh" material="default_material" pos="0 0 0" quat="1 0 0 0" mesh="left_end_effector_link.STL"/></body></body></body></body></body></body><body name="right_upper_arm_pitch_link" pos="0 -0.097650000000000001 0" quat="1 0 0 0"><joint name="right_shoulder_pitch_joint" type="hinge" axis="0 1 0" range="-2.9660000000000002 2.9660000000000002"/><inertial pos="-0.00045951999999999999 -0.060859000000000003 -7.7299999999999995e-05" quat="1 0 0 0" mass="0.88500000000000001" diaginertia="0.16842761913930798 0.16811168913930799 0.16840614913930799"/><geom name="right_upper_arm_pitch_link_visual" class="visual" type="mesh" material="default_material" pos="0 0 0" quat="1 0 0 0" mesh="right_upper_arm_pitch_link.STL"/><body name="right_upper_arm_roll_link" pos="0 -0.078 0" quat="1 0 0 0"><joint name="right_shoulder_roll_joint" type="hinge" axis="1 0 0" range="-2.7919999999999998 0.17399999999999999"/><inertial pos="0.0049503999999999998 -0.0005218 -0.043376999999999999" quat="1 0 0 0" mass="0.71599999999999997" diaginertia="0.033068 0.0331785 0.031771690000000005"/><geom name="right_upper_arm_roll_link_collision" class="collision" type="sphere" pos="0 0 0" quat="1 0 0 0" size="0.032000000000000001"/><geom name="right_upper_arm_roll_link_visual" class="visual" type="mesh" material="default_material" pos="0 0 0" quat="1 0 0 0" mesh="right_upper_arm_roll_link.STL"/><body name="right_upper_arm_yaw_link" pos="0 0 -0.10050000000000001" quat="1 0 0 0"><joint name="right_shoulder_yaw_joint" type="hinge" axis="0 0 1" range="-1.8320000000000001 1.8320000000000001"/><inertial pos="0 0.00055668999999999998 -0.060728999999999998" quat="1 0 0 0" mass="0.91300000000000003" diaginertia="0.034176700000000004 0.034196400000000002 0.031887490000000004"/><geom name="right_upper_arm_yaw_link_collision" class="collision" type="cylinder" pos="0 0 0" quat="1 0 0 0" size="0.032000000000000001 0.059999999999999998"/><geom name="right_upper_arm_yaw_link_visual" class="visual" type="mesh" material="default_material" pos="0 0 0" quat="1 0 0 0" mesh="right_upper_arm_yaw_link.STL"/><body name="right_lower_arm_pitch_link" pos="0 0 -0.1095" quat="-0.70710548251688432 8.6595605623403291e-17 0.70710807985382562 8.6595605623403291e-17"><joint name="right_elbow_pitch_joint" type="hinge" axis="0 1 0" range="-0.34899999999999998 1.6579999999999999"/><inertial pos="-0.0005218 -0.0049503999999999998 -0.043376999999999999" quat="1 0 0 0" mass="0.71599999999999997" diaginertia="0.0331785 0.033068 0.031771690000000005"/><geom name="right_lower_arm_pitch_link_visual" class="visual" type="mesh" material="default_material" pos="0 0 0" quat="1 0 0 0" mesh="right_lower_arm_pitch_link.STL"/><body name="right_hand_yaw_link" pos="0 0 -0.10050000000000001" quat="1 0 0 0"><joint name="right_wrist_yaw_joint" type="hinge" axis="0 0 1" range="-1.8320000000000001 1.8320000000000001"/><inertial pos="-0.00020719 -1.9400000000000001e-05 -0.013715" quat="1 0 0 0" mass="0.44" diaginertia="0.031714470000000002 0.031691070000000002 0.03155227"/><geom name="right_hand_yaw_link_collision" class="collision" type="cylinder" pos="0 0 0" quat="1 0 0 0" size="0.032000000000000001 0.059999999999999998"/><geom name="right_hand_yaw_link_visual" class="visual" type="mesh" material="default_material" pos="0 0 0" quat="1 0 0 0" mesh="right_hand_yaw_link.STL"/><body name="right_end_effector_link" pos="0 0 -0.1045" quat="1 0 0 0"><inertial pos="0.0034650000000000002 0 0" quat="1 0 0 0" mass="0.099400000000000002" diaginertia="3.7410000000000003e-05 3.7410000000000003e-05 4.5380000000000003e-05"/><geom name="right_end_effector_link_collision" class="collision" type="sphere" pos="0 0 0" quat="1 0 0 0" size="0.02751"/><geom name="right_end_effector_link_visual" class="visual" type="mesh" material="default_material" pos="0 0 0" quat="1 0 0 0" mesh="right_end_effector_link.STL"/></body></body></body></body></body></body></body></body></body></worldbody><actuator><motor name="left_hip_pitch_joint_ctrl" joint="left_hip_pitch_joint"/><motor name="left_hip_roll_joint_ctrl" joint="left_hip_roll_joint"/><motor name="left_hip_yaw_joint_ctrl" joint="left_hip_yaw_joint"/><motor name="left_knee_pitch_joint_ctrl" joint="left_knee_pitch_joint"/><motor name="left_ankle_roll_joint_ctrl" joint="left_ankle_roll_joint"/><motor name="left_ankle_pitch_joint_ctrl" joint="left_ankle_pitch_joint"/><motor name="right_hip_pitch_joint_ctrl" joint="right_hip_pitch_joint"/><motor name="right_hip_roll_joint_ctrl" joint="right_hip_roll_joint"/><motor name="right_hip_yaw_joint_ctrl" joint="right_hip_yaw_joint"/><motor name="right_knee_pitch_joint_ctrl" joint="right_knee_pitch_joint"/><motor name="right_ankle_roll_joint_ctrl" joint="right_ankle_roll_joint"/><motor name="right_ankle_pitch_joint_ctrl" joint="right_ankle_pitch_joint"/><motor name="waist_yaw_joint_ctrl" joint="waist_yaw_joint"/><motor name="left_shoulder_pitch_joint_ctrl" joint="left_shoulder_pitch_joint"/><motor name="left_shoulder_roll_joint_ctrl" joint="left_shoulder_roll_joint"/><motor name="left_shoulder_yaw_joint_ctrl" joint="left_shoulder_yaw_joint"/><motor name="left_elbow_pitch_joint_ctrl" joint="left_elbow_pitch_joint"/><motor name="left_wrist_yaw_joint_ctrl" joint="left_wrist_yaw_joint"/><motor name="right_shoulder_pitch_joint_ctrl" joint="right_shoulder_pitch_joint"/><motor name="right_shoulder_roll_joint_ctrl" joint="right_shoulder_roll_joint"/><motor name="right_shoulder_yaw_joint_ctrl" joint="right_shoulder_yaw_joint"/><motor name="right_elbow_pitch_joint_ctrl" joint="right_elbow_pitch_joint"/><motor name="right_wrist_yaw_joint_ctrl" joint="right_wrist_yaw_joint"/></actuator><contact><exclude body1="right_thigh_yaw_link" body2="right_shank_pitch_link"/><exclude body1="right_thigh_roll_link" body2="right_thigh_yaw_link"/><exclude body1="right_hand_yaw_link" body2="right_end_effector_link"/><exclude body1="right_upper_arm_roll_link" body2="right_upper_arm_yaw_link"/><exclude body1="left_upper_arm_roll_link" body2="left_upper_arm_yaw_link"/><exclude body1="left_thigh_yaw_link" body2="left_shank_pitch_link"/><exclude body1="base_link" body2="waist_yaw_link"/><exclude body1="left_hand_yaw_link" body2="left_end_effector_link"/><exclude body1="waist_yaw_link" body2="torso_link"/><exclude body1="left_thigh_roll_link" body2="left_thigh_yaw_link"/></contact></mujoco>