<mujoco model="g1_29dof"><compiler angle="radian" autolimits="true"/><asset><material name="dark" rgba="0.20000000298023224 0.20000000298023224 0.20000000298023224 1"/><material name="white" rgba="0.69999998807907104 0.69999998807907104 0.69999998807907104 1"/><material name="default_material" rgba="0.7 0.7 0.7 1"/><mesh name="waist_support_link.STL" file="../meshes/waist_support_link.STL"/><mesh name="right_rubber_hand.STL" file="../meshes/right_rubber_hand.STL"/><mesh name="right_wrist_yaw_link.STL" file="../meshes/right_wrist_yaw_link.STL"/><mesh name="right_wrist_roll_link.STL" file="../meshes/right_wrist_roll_link.STL"/><mesh name="right_shoulder_yaw_link.STL" file="../meshes/right_shoulder_yaw_link.STL"/><mesh name="right_ankle_pitch_link.STL" file="../meshes/right_ankle_pitch_link.STL"/><mesh name="right_knee_link.STL" file="../meshes/right_knee_link.STL"/><mesh name="right_hip_yaw_link.STL" file="../meshes/right_hip_yaw_link.STL"/><mesh name="pelvis_contour_link.STL" file="../meshes/pelvis_contour_link.STL"/><mesh name="left_shoulder_pitch_link.STL" file="../meshes/left_shoulder_pitch_link.STL"/><mesh name="left_ankle_roll_link.STL" file="../meshes/left_ankle_roll_link.STL"/><mesh name="right_hip_roll_link.STL" file="../meshes/right_hip_roll_link.STL"/><mesh name="right_wrist_pitch_link.STL" file="../meshes/right_wrist_pitch_link.STL"/><mesh name="left_ankle_pitch_link.STL" file="../meshes/left_ankle_pitch_link.STL"/><mesh name="right_hip_pitch_link.STL" file="../meshes/right_hip_pitch_link.STL"/><mesh name="left_hip_roll_link.STL" file="../meshes/left_hip_roll_link.STL"/><mesh name="left_knee_link.STL" file="../meshes/left_knee_link.STL"/><mesh name="pelvis.STL" file="../meshes/pelvis.STL"/><mesh name="right_ankle_roll_link.STL" file="../meshes/right_ankle_roll_link.STL"/><mesh name="waist_yaw_link.STL" file="../meshes/waist_yaw_link.STL"/><mesh name="waist_roll_link.STL" file="../meshes/waist_roll_link.STL"/><mesh name="torso_link.STL" file="../meshes/torso_link.STL"/><mesh name="left_hip_pitch_link.STL" file="../meshes/left_hip_pitch_link.STL"/><mesh name="head_link.STL" file="../meshes/head_link.STL"/><mesh name="left_wrist_yaw_link.STL" file="../meshes/left_wrist_yaw_link.STL"/><mesh name="left_shoulder_roll_link.STL" file="../meshes/left_shoulder_roll_link.STL"/><mesh name="left_shoulder_yaw_link.STL" file="../meshes/left_shoulder_yaw_link.STL"/><mesh name="left_wrist_pitch_link.STL" file="../meshes/left_wrist_pitch_link.STL"/><mesh name="right_elbow_link.STL" file="../meshes/right_elbow_link.STL"/><mesh name="left_rubber_hand.STL" file="../meshes/left_rubber_hand.STL"/><mesh name="left_elbow_link.STL" file="../meshes/left_elbow_link.STL"/><mesh name="logo_link.STL" file="../meshes/logo_link.STL"/><mesh name="left_hip_yaw_link.STL" file="../meshes/left_hip_yaw_link.STL"/><mesh name="right_shoulder_pitch_link.STL" file="../meshes/right_shoulder_pitch_link.STL"/><mesh name="left_wrist_roll_link.STL" file="../meshes/left_wrist_roll_link.STL"/><mesh name="right_shoulder_roll_link.STL" file="../meshes/right_shoulder_roll_link.STL"/></asset><default><default class="visual"><geom group="2" contype="0" conaffinity="0"/></default><default class="collision"><geom group="3" mass="0" density="0"/></default></default><worldbody><light name="key_light" mode="targetbody" target="pelvis" pos="3 -3 4" diffuse="0.95 0.95 0.95" specular="0.2 0.2 0.2"/><light name="fill_light" directional="true" dir="-0.2 -0.1 -1" diffuse="0.35 0.35 0.35" specular="0.08 0.08 0.08"/><geom name="floor" type="plane" size="0 0 0.05" rgba="0.2 0.3 0.4 1"/><body name="pelvis" pos="0 0 0" quat="1 0 0 0"><freejoint name="base_free_joint"/><inertial pos="0 0 -0.076050000000000006" quat="1 0 0 0" mass="3.8130000000000002" diaginertia="0.010548999999999999 0.0093089000000000002 0.0079184000000000008"/><geom name="pelvis_visual" class="visual" type="mesh" material="dark" pos="0 0 0" quat="1 0 0 0" mesh="pelvis.STL"/><body name="imu_in_pelvis" pos="0.045249999999999999 0 -0.083390000000000006" quat="1 0 0 0"></body><body name="left_hip_pitch_link" pos="0 0.064451999999999995 -0.1027" quat="1 0 0 0"><joint name="left_hip_pitch_joint" type="hinge" axis="0 1 0" range="-1.5700000000000001 1.5700000000000001"/><inertial pos="0.0027409999999999999 0.047791 -0.02606" quat="1 0 0 0" mass="1.3500000000000001" diaginertia="0.0018109999999999999 0.0014193000000000001 0.0012811999999999999"/><geom name="left_hip_pitch_link_collision" class="collision" type="mesh" pos="0 0 0" quat="1 0 0 0" mesh="left_hip_pitch_link.STL"/><geom name="left_hip_pitch_link_visual" class="visual" type="mesh" material="dark" pos="0 0 0" quat="1 0 0 0" mesh="left_hip_pitch_link.STL"/><body name="left_hip_roll_link" pos="0 0.051999999999999998 -0.030464999999999999" quat="0.99617868497449569 0 -0.087338580263732479 0"><joint name="left_hip_roll_joint" type="hinge" axis="1 0 0" range="-0.52359999999999995 1.5700000000000001"/><inertial pos="0.029812000000000002 -0.0010449999999999999 -0.087933999999999998" quat="1 0 0 0" mass="1.52" diaginertia="0.0023773000000000002 0.0024123 0.0016595"/><geom name="left_hip_roll_link_collision" class="collision" type="mesh" pos="0 0 0" quat="1 0 0 0" mesh="left_hip_roll_link.STL"/><geom name="left_hip_roll_link_visual" class="visual" type="mesh" material="white" pos="0 0 0" quat="1 0 0 0" mesh="left_hip_roll_link.STL"/><body name="left_hip_yaw_link" pos="0.025000999999999999 0 -0.12411999999999999" quat="1 0 0 0"><joint name="left_hip_yaw_joint" type="hinge" axis="0 0 1" range="-1.5700000000000001 1.5700000000000001"/><inertial pos="-0.057709000000000003 -0.010980999999999999 -0.15078" quat="1 0 0 0" mass="1.702" diaginertia="0.0057774000000000002 0.0076124000000000001 0.0031489999999999999"/><geom name="left_hip_yaw_link_collision" class="collision" type="mesh" pos="0 0 0" quat="1 0 0 0" mesh="left_hip_yaw_link.STL"/><geom name="left_hip_yaw_link_visual" class="visual" type="mesh" material="white" pos="0 0 0" quat="1 0 0 0" mesh="left_hip_yaw_link.STL"/><body name="left_knee_link" pos="-0.078272999999999995 0.0021489 -0.17734" quat="0.99617868497449569 0 0.087338580263732479 0"><joint name="left_knee_joint" type="hinge" axis="0 1 0" range="-0.087266999999999997 2.8797999999999999"/><inertial pos="0.005457 0.0039639999999999996 -0.12074" quat="1 0 0 0" mass="1.9319999999999999" diaginertia="0.011329000000000001 0.011277000000000001 0.0015168"/><geom name="left_knee_link_collision" class="collision" type="mesh" pos="0 0 0" quat="1 0 0 0" mesh="left_knee_link.STL"/><geom name="left_knee_link_visual" class="visual" type="mesh" material="white" pos="0 0 0" quat="1 0 0 0" mesh="left_knee_link.STL"/><body name="left_ankle_pitch_link" pos="0 -9.4444999999999994e-05 -0.30001" quat="1 0 0 0"><joint name="left_ankle_pitch_joint" type="hinge" axis="0 1 0" range="-0.87266999999999995 0.52359999999999995"/><inertial pos="-0.0072690000000000003 0 0.011136999999999999" quat="1 0 0 0" mass="0.073999999999999996" diaginertia="8.3999999999999992e-06 1.8899999999999999e-05 1.26e-05"/><geom name="left_ankle_pitch_link_collision" class="collision" type="mesh" pos="0 0 0" quat="1 0 0 0" mesh="left_ankle_pitch_link.STL"/><geom name="left_ankle_pitch_link_visual" class="visual" type="mesh" material="white" pos="0 0 0" quat="1 0 0 0" mesh="left_ankle_pitch_link.STL"/><body name="left_ankle_roll_link" pos="0 0 -0.017558000000000001" quat="1 0 0 0"><joint name="left_ankle_roll_joint" type="hinge" axis="1 0 0" range="-0.26179999999999998 0.26179999999999998"/><inertial pos="0.026505000000000001 0 -0.016424999999999999" quat="1 0 0 0" mass="0.60799999999999998" diaginertia="0.0002231 0.0016161000000000001 0.0016666999999999999"/><geom name="left_ankle_roll_link_collision_0" class="collision" type="sphere" pos="-0.050000000000000003 0.025000000000000001 -0.029999999999999999" quat="1 0 0 0" size="0.0050000000000000001"/><geom name="left_ankle_roll_link_collision_1" class="collision" type="sphere" pos="-0.050000000000000003 -0.025000000000000001 -0.029999999999999999" quat="1 0 0 0" size="0.0050000000000000001"/><geom name="left_ankle_roll_link_collision_2" class="collision" type="sphere" pos="0.12 0.029999999999999999 -0.029999999999999999" quat="1 0 0 0" size="0.0050000000000000001"/><geom name="left_ankle_roll_link_collision_3" class="collision" type="sphere" pos="0.12 -0.029999999999999999 -0.029999999999999999" quat="1 0 0 0" size="0.0050000000000000001"/><geom name="left_ankle_roll_link_visual" class="visual" type="mesh" material="dark" pos="0 0 0" quat="1 0 0 0" mesh="left_ankle_roll_link.STL"/><body name="left_toe_link" pos="0.10000000000000001 0 -0.02" quat="1 0 0 0"></body></body></body></body></body></body></body><body name="pelvis_contour_link" pos="0 0 0" quat="1 0 0 0"><inertial pos="0 0 0" quat="1 0 0 0" mass="0.001" diaginertia="9.9999999999999995e-08 9.9999999999999995e-08 9.9999999999999995e-08"/><geom name="pelvis_contour_link_collision" class="collision" type="mesh" pos="0 0 0" quat="1 0 0 0" mesh="pelvis_contour_link.STL"/><geom name="pelvis_contour_link_visual" class="visual" type="mesh" material="white" pos="0 0 0" quat="1 0 0 0" mesh="pelvis_contour_link.STL"/></body><body name="right_hip_pitch_link" pos="0 -0.064451999999999995 -0.1027" quat="1 0 0 0"><joint name="right_hip_pitch_joint" type="hinge" axis="0 1 0" range="-1.5700000000000001 1.5700000000000001"/><inertial pos="0.0027409999999999999 -0.047791 -0.02606" quat="1 0 0 0" mass="1.3500000000000001" diaginertia="0.0018109999999999999 0.0014193000000000001 0.0012811999999999999"/><geom name="right_hip_pitch_link_collision" class="collision" type="mesh" pos="0 0 0" quat="1 0 0 0" mesh="right_hip_pitch_link.STL"/><geom name="right_hip_pitch_link_visual" class="visual" type="mesh" material="dark" pos="0 0 0" quat="1 0 0 0" mesh="right_hip_pitch_link.STL"/><body name="right_hip_roll_link" pos="0 -0.051999999999999998 -0.030464999999999999" quat="0.99617868497449569 0 -0.087338580263732479 0"><joint name="right_hip_roll_joint" type="hinge" axis="1 0 0" range="-1.5700000000000001 0.52359999999999995"/><inertial pos="0.029812000000000002 0.0010449999999999999 -0.087933999999999998" quat="1 0 0 0" mass="1.52" diaginertia="0.0023773000000000002 0.0024123 0.0016595"/><geom name="right_hip_roll_link_collision" class="collision" type="mesh" pos="0 0 0" quat="1 0 0 0" mesh="right_hip_roll_link.STL"/><geom name="right_hip_roll_link_visual" class="visual" type="mesh" material="white" pos="0 0 0" quat="1 0 0 0" mesh="right_hip_roll_link.STL"/><body name="right_hip_yaw_link" pos="0.025000999999999999 0 -0.12411999999999999" quat="1 0 0 0"><joint name="right_hip_yaw_joint" type="hinge" axis="0 0 1" range="-1.5700000000000001 1.5700000000000001"/><inertial pos="-0.057709000000000003 0.010980999999999999 -0.15078" quat="1 0 0 0" mass="1.702" diaginertia="0.0057774000000000002 0.0076124000000000001 0.0031489999999999999"/><geom name="right_hip_yaw_link_collision" class="collision" type="mesh" pos="0 0 0" quat="1 0 0 0" mesh="right_hip_yaw_link.STL"/><geom name="right_hip_yaw_link_visual" class="visual" type="mesh" material="white" pos="0 0 0" quat="1 0 0 0" mesh="right_hip_yaw_link.STL"/><body name="right_knee_link" pos="-0.078272999999999995 -0.0021489 -0.17734" quat="0.99617868497449569 0 0.087338580263732479 0"><joint name="right_knee_joint" type="hinge" axis="0 1 0" range="-0.087266999999999997 2.8797999999999999"/><inertial pos="0.005457 -0.0039639999999999996 -0.12074" quat="1 0 0 0" mass="1.9319999999999999" diaginertia="0.011329000000000001 0.011277000000000001 0.0015168"/><geom name="right_knee_link_collision" class="collision" type="mesh" pos="0 0 0" quat="1 0 0 0" mesh="right_knee_link.STL"/><geom name="right_knee_link_visual" class="visual" type="mesh" material="white" pos="0 0 0" quat="1 0 0 0" mesh="right_knee_link.STL"/><body name="right_ankle_pitch_link" pos="0 9.4444999999999994e-05 -0.30001" quat="1 0 0 0"><joint name="right_ankle_pitch_joint" type="hinge" axis="0 1 0" range="-0.87266999999999995 0.52359999999999995"/><inertial pos="-0.0072690000000000003 0 0.011136999999999999" quat="1 0 0 0" mass="0.073999999999999996" diaginertia="8.3999999999999992e-06 1.8899999999999999e-05 1.26e-05"/><geom name="right_ankle_pitch_link_collision" class="collision" type="mesh" pos="0 0 0" quat="1 0 0 0" mesh="right_ankle_pitch_link.STL"/><geom name="right_ankle_pitch_link_visual" class="visual" type="mesh" material="white" pos="0 0 0" quat="1 0 0 0" mesh="right_ankle_pitch_link.STL"/><body name="right_ankle_roll_link" pos="0 0 -0.017558000000000001" quat="1 0 0 0"><joint name="right_ankle_roll_joint" type="hinge" axis="1 0 0" range="-0.26179999999999998 0.26179999999999998"/><inertial pos="0.026505000000000001 0 -0.016424999999999999" quat="1 0 0 0" mass="0.60799999999999998" diaginertia="0.0002231 0.0016161000000000001 0.0016666999999999999"/><geom name="right_ankle_roll_link_collision_0" class="collision" type="sphere" pos="-0.050000000000000003 0.025000000000000001 -0.029999999999999999" quat="1 0 0 0" size="0.0050000000000000001"/><geom name="right_ankle_roll_link_collision_1" class="collision" type="sphere" pos="-0.050000000000000003 -0.025000000000000001 -0.029999999999999999" quat="1 0 0 0" size="0.0050000000000000001"/><geom name="right_ankle_roll_link_collision_2" class="collision" type="sphere" pos="0.12 0.029999999999999999 -0.029999999999999999" quat="1 0 0 0" size="0.0050000000000000001"/><geom name="right_ankle_roll_link_collision_3" class="collision" type="sphere" pos="0.12 -0.029999999999999999 -0.029999999999999999" quat="1 0 0 0" size="0.0050000000000000001"/><geom name="right_ankle_roll_link_visual" class="visual" type="mesh" material="dark" pos="0 0 0" quat="1 0 0 0" mesh="right_ankle_roll_link.STL"/><body name="right_toe_link" pos="0.10000000000000001 0 -0.02" quat="1 0 0 0"></body></body></body></body></body></body></body><body name="waist_yaw_link" pos="0 0 0" quat="1 0 0 0"><joint name="waist_yaw_joint" type="hinge" axis="0 0 1" range="-1.5700000000000001 1.5700000000000001"/><inertial pos="0.0039639999999999996 0 0.018769000000000001" quat="1 0 0 0" mass="0.24399999999999999" diaginertia="9.9586999999999994e-05 0.00012411 0.00015585999999999999"/><geom name="waist_yaw_link_visual" class="visual" type="mesh" material="white" pos="0 0 0" quat="1 0 0 0" mesh="waist_yaw_link.STL"/><body name="waist_roll_link" pos="-0.0039635 0 0.035000000000000003" quat="1 0 0 0"><joint name="waist_roll_joint" type="hinge" axis="1 0 0" range="-0.10000000000000001 0.10000000000000001"/><inertial pos="0 -0.00023599999999999999 0.010111" quat="1 0 0 0" mass="0.047" diaginertia="7.515e-06 6.3980000000000004e-06 3.9879999999999998e-06"/><geom name="waist_roll_link_visual" class="visual" type="mesh" material="white" pos="0 0 0" quat="1 0 0 0" mesh="waist_roll_link.STL"/><body name="torso_link" pos="0 0 0.019" quat="1 0 0 0"><joint name="waist_pitch_joint" type="hinge" axis="0 1 0" range="-0.52000000000000002 0.52000000000000002"/><inertial pos="0.002601 0.00025700000000000001 0.15371899999999999" quat="1 0 0 0" mass="8.5619999999999994" diaginertia="0.065674966000000001 0.053535187999999997 0.030808124999999999"/><geom name="torso_link_collision" class="collision" type="mesh" pos="0 0 0" quat="1 0 0 0" mesh="torso_link.STL"/><geom name="torso_link_visual" class="visual" type="mesh" material="white" pos="0 0 0" quat="1 0 0 0" mesh="torso_link.STL"/><body name="d435_link" pos="0.057623500000000001 0.01753 0.41987000000000002" quat="0.91495966784982474 0 0.40354529635239006 0"></body><body name="head_link" pos="0.0039635 0 -0.053999999999999999" quat="1 0 0 0"><inertial pos="0.005267 0.000299 0.44986900000000002" quat="1 0 0 0" mass="1.036" diaginertia="0.0040850510000000001 0.0041852119999999998 0.0018079109999999999"/><geom name="head_link_collision" class="collision" type="mesh" pos="0 0 0" quat="1 0 0 0" mesh="head_link.STL"/><geom name="head_link_visual" class="visual" type="mesh" material="dark" pos="0 0 0" quat="1 0 0 0" mesh="head_link.STL"/></body><body name="imu_in_torso" pos="-0.03959 -0.0022399999999999998 0.13791999999999999" quat="1 0 0 0"></body><body name="left_shoulder_pitch_link" pos="0.0039563000000000003 0.10022 0.23777999999999999" quat="0.99026407437221953 0.1392014837428143 1.3872204401988457e-05 -9.8686838424204382e-05"><joint name="left_shoulder_pitch_joint" type="hinge" axis="0 1 0" range="-3.0891999999999999 1.149"/><inertial pos="0 0.035892 -0.011627999999999999" quat="1 0 0 0" mass="0.71799999999999997" diaginertia="0.00042910000000000002 0.00045300000000000001 0.00042299999999999998"/><geom name="left_shoulder_pitch_link_collision" class="collision" type="cylinder" pos="0 0.040000000000000001 -0.01" quat="0.70710678118654757 0 0.70710678118654746 0" size="0.029999999999999999 0.025000000000000001"/><geom name="left_shoulder_pitch_link_visual" class="visual" type="mesh" material="white" pos="0 0 0" quat="1 0 0 0" mesh="left_shoulder_pitch_link.STL"/><body name="left_shoulder_roll_link" pos="0 0.037999999999999999 -0.013831" quat="0.99026825525484086 -0.13917177384273471 0 0"><joint name="left_shoulder_roll_joint" type="hinge" axis="1 0 0" range="-0.59999999999999998 2.2515000000000001"/><inertial pos="-0.00022699999999999999 0.0072700000000000004 -0.063242999999999994" quat="1 0 0 0" mass="0.64300000000000002" diaginertia="0.0006177 0.0006912 0.00038939999999999998"/><geom name="left_shoulder_roll_link_collision" class="collision" type="cylinder" pos="-0.0040000000000000001 0.0060000000000000001 -0.052999999999999999" quat="1 0 0 0" size="0.029999999999999999 0.014999999999999999"/><geom name="left_shoulder_roll_link_visual" class="visual" type="mesh" material="white" pos="0 0 0" quat="1 0 0 0" mesh="left_shoulder_roll_link.STL"/><body name="left_shoulder_yaw_link" pos="0 0.0062399999999999999 -0.1032" quat="1 0 0 0"><joint name="left_shoulder_yaw_joint" type="hinge" axis="0 0 1" range="-1.3999999999999999 2"/><inertial pos="0.010773 -0.0029489999999999998 -0.072009000000000004" quat="1 0 0 0" mass="0.73399999999999999" diaginertia="0.00099879999999999999 0.0010605 0.00043540000000000001"/><geom name="left_shoulder_yaw_link_collision" class="collision" type="mesh" pos="0 0 0" quat="1 0 0 0" mesh="left_shoulder_yaw_link.STL"/><geom name="left_shoulder_yaw_link_visual" class="visual" type="mesh" material="white" pos="0 0 0" quat="1 0 0 0" mesh="left_shoulder_yaw_link.STL"/><body name="left_elbow_link" pos="0.015782999999999998 0 -0.080518000000000006" quat="1 0 0 0"><joint name="left_elbow_joint" type="hinge" axis="0 1 0" range="-1.0471999999999999 1.7"/><inertial pos="0.064956 0.0044539999999999996 -0.010062" quat="1 0 0 0" mass="0.59999999999999998" diaginertia="0.00028909999999999998 0.00041520000000000001 0.00041970000000000001"/><geom name="left_elbow_link_collision" class="collision" type="mesh" pos="0 0 0" quat="1 0 0 0" mesh="left_elbow_link.STL"/><geom name="left_elbow_link_visual" class="visual" type="mesh" material="white" pos="0 0 0" quat="1 0 0 0" mesh="left_elbow_link.STL"/><body name="left_wrist_roll_link" pos="0.10000000000000001 0.00188791 -0.01" quat="1 0 0 0"><joint name="left_wrist_roll_joint" type="hinge" axis="1 0 0" range="-1.9722200000000001 1.9722200000000001"/><inertial pos="0.017139447780000001 0.00053759094000000005 4.8864000000000001e-07" quat="1 0 0 0" mass="0.085444980000000004" diaginertia="4.8215440230000001e-05 3.7228990929999999e-05 5.4821065410000003e-05"/><geom name="left_wrist_roll_link_collision" class="collision" type="mesh" pos="0 0 0" quat="1 0 0 0" mesh="left_wrist_roll_link.STL"/><geom name="left_wrist_roll_link_visual" class="visual" type="mesh" material="white" pos="0 0 0" quat="1 0 0 0" mesh="left_wrist_roll_link.STL"/><body name="left_wrist_pitch_link" pos="0.037999999999999999 0 0" quat="1 0 0 0"><joint name="left_wrist_pitch_joint" type="hinge" axis="0 1 0" range="-1.6144295580000001 1.6144295580000001"/><inertial pos="0.022999898370000001 -0.00111685314 -0.0011165809599999999" quat="1 0 0 0" mass="0.48404955999999999" diaginertia="0.00016579646273 0.00042954057410000003 0.00042953697654000002"/><geom name="left_wrist_pitch_link_collision" class="collision" type="mesh" pos="0 0 0" quat="1 0 0 0" mesh="left_wrist_pitch_link.STL"/><geom name="left_wrist_pitch_link_visual" class="visual" type="mesh" material="white" pos="0 0 0" quat="1 0 0 0" mesh="left_wrist_pitch_link.STL"/><body name="left_wrist_yaw_link" pos="0.045999999999999999 0 0" quat="1 0 0 0"><joint name="left_wrist_yaw_joint" type="hinge" axis="0 0 1" range="-1.6144295580000001 1.6144295580000001"/><inertial pos="0.02200381568 0.00049485095999999998 0.00053861122999999999" quat="1 0 0 0" mass="0.084576470000000001" diaginertia="4.9291288280000003e-05 5.9733381340000002e-05 3.9280838259999998e-05"/><geom name="left_wrist_yaw_link_collision" class="collision" type="mesh" pos="0 0 0" quat="1 0 0 0" mesh="left_wrist_yaw_link.STL"/><geom name="left_wrist_yaw_link_visual" class="visual" type="mesh" material="white" pos="0 0 0" quat="1 0 0 0" mesh="left_wrist_yaw_link.STL"/><body name="left_rubber_hand" pos="0.041500000000000002 0.0030000000000000001 0" quat="1 0 0 0"><inertial pos="0.053613108079999999 -0.0029590523999999999 0.00215413091" quat="1 0 0 0" mass="0.17000000000000001" diaginertia="0.00010099485234748001 0.00028135871571620998 0.00021894770413514"/><geom name="left_rubber_hand_visual" class="visual" type="mesh" material="white" pos="0 0 0" quat="1 0 0 0" mesh="left_rubber_hand.STL"/></body></body></body></body></body></body></body></body><body name="logo_link" pos="0.0039635 0 -0.053999999999999999" quat="1 0 0 0"><inertial pos="0 0 0" quat="1 0 0 0" mass="0.001" diaginertia="9.9999999999999995e-08 9.9999999999999995e-08 9.9999999999999995e-08"/><geom name="logo_link_collision" class="collision" type="mesh" pos="0 0 0" quat="1 0 0 0" mesh="logo_link.STL"/><geom name="logo_link_visual" class="visual" type="mesh" material="dark" pos="0 0 0" quat="1 0 0 0" mesh="logo_link.STL"/></body><body name="mid360_link" pos="0.00028350000000000001 3.0000000000000001e-05 0.40617999999999999" quat="0.99979857849329978 0 0.020069938783589012 0"></body><body name="right_shoulder_pitch_link" pos="0.0039563000000000003 -0.10020999999999999 0.23777999999999999" quat="0.99026407437221953 -0.1392014837428143 1.3872204401988457e-05 9.8686838424204382e-05"><joint name="right_shoulder_pitch_joint" type="hinge" axis="0 1 0" range="-3.0891999999999999 1.149"/><inertial pos="0 -0.035892 -0.011627999999999999" quat="1 0 0 0" mass="0.71799999999999997" diaginertia="0.00042910000000000002 0.00045300000000000001 0.00042299999999999998"/><geom name="right_shoulder_pitch_link_collision" class="collision" type="cylinder" pos="0 -0.040000000000000001 -0.01" quat="0.70710678118654757 0 0.70710678118654746 0" size="0.029999999999999999 0.025000000000000001"/><geom name="right_shoulder_pitch_link_visual" class="visual" type="mesh" material="white" pos="0 0 0" quat="1 0 0 0" mesh="right_shoulder_pitch_link.STL"/><body name="right_shoulder_roll_link" pos="0 -0.037999999999999999 -0.013831" quat="0.99026825525484086 0.13917177384273471 0 0"><joint name="right_shoulder_roll_joint" type="hinge" axis="1 0 0" range="-2.2515000000000001 0.59999999999999998"/><inertial pos="-0.00022699999999999999 -0.0072700000000000004 -0.063242999999999994" quat="1 0 0 0" mass="0.64300000000000002" diaginertia="0.0006177 0.0006912 0.00038939999999999998"/><geom name="right_shoulder_roll_link_collision" class="collision" type="cylinder" pos="-0.0040000000000000001 -0.0060000000000000001 -0.052999999999999999" quat="1 0 0 0" size="0.029999999999999999 0.014999999999999999"/><geom name="right_shoulder_roll_link_visual" class="visual" type="mesh" material="white" pos="0 0 0" quat="1 0 0 0" mesh="right_shoulder_roll_link.STL"/><body name="right_shoulder_yaw_link" pos="0 -0.0062399999999999999 -0.1032" quat="1 0 0 0"><joint name="right_shoulder_yaw_joint" type="hinge" axis="0 0 1" range="-2 1.3999999999999999"/><inertial pos="0.010773 0.0029489999999999998 -0.072009000000000004" quat="1 0 0 0" mass="0.73399999999999999" diaginertia="0.00099879999999999999 0.0010605 0.00043540000000000001"/><geom name="right_shoulder_yaw_link_collision" class="collision" type="mesh" pos="0 0 0" quat="1 0 0 0" mesh="right_shoulder_yaw_link.STL"/><geom name="right_shoulder_yaw_link_visual" class="visual" type="mesh" material="white" pos="0 0 0" quat="1 0 0 0" mesh="right_shoulder_yaw_link.STL"/><body name="right_elbow_link" pos="0.015782999999999998 0 -0.080518000000000006" quat="1 0 0 0"><joint name="right_elbow_joint" type="hinge" axis="0 1 0" range="-1.0471999999999999 1.7"/><inertial pos="0.064956 -0.0044539999999999996 -0.010062" quat="1 0 0 0" mass="0.59999999999999998" diaginertia="0.00028909999999999998 0.00041520000000000001 0.00041970000000000001"/><geom name="right_elbow_link_collision" class="collision" type="mesh" pos="0 0 0" quat="1 0 0 0" mesh="right_elbow_link.STL"/><geom name="right_elbow_link_visual" class="visual" type="mesh" material="white" pos="0 0 0" quat="1 0 0 0" mesh="right_elbow_link.STL"/><body name="right_wrist_roll_link" pos="0.10000000000000001 -0.00188791 -0.01" quat="1 0 0 0"><joint name="right_wrist_roll_joint" type="hinge" axis="1 0 0" range="-1.9722200000000001 1.9722200000000001"/><inertial pos="0.017139447780000001 -0.00053759094000000005 4.8864000000000001e-07" quat="1 0 0 0" mass="0.085444980000000004" diaginertia="4.8215440230000001e-05 3.7228990929999999e-05 5.4821065410000003e-05"/><geom name="right_wrist_roll_link_collision" class="collision" type="mesh" pos="0 0 0" quat="1 0 0 0" mesh="right_wrist_roll_link.STL"/><geom name="right_wrist_roll_link_visual" class="visual" type="mesh" material="white" pos="0 0 0" quat="1 0 0 0" mesh="right_wrist_roll_link.STL"/><body name="right_wrist_pitch_link" pos="0.037999999999999999 0 0" quat="1 0 0 0"><joint name="right_wrist_pitch_joint" type="hinge" axis="0 1 0" range="-1.6144295580000001 1.6144295580000001"/><inertial pos="0.022999898370000001 0.00111685314 -0.0011165809599999999" quat="1 0 0 0" mass="0.48404955999999999" diaginertia="0.00016579646273 0.00042954057410000003 0.00042953697654000002"/><geom name="right_wrist_pitch_link_collision" class="collision" type="mesh" pos="0 0 0" quat="1 0 0 0" mesh="right_wrist_pitch_link.STL"/><geom name="right_wrist_pitch_link_visual" class="visual" type="mesh" material="white" pos="0 0 0" quat="1 0 0 0" mesh="right_wrist_pitch_link.STL"/><body name="right_wrist_yaw_link" pos="0.045999999999999999 0 0" quat="1 0 0 0"><joint name="right_wrist_yaw_joint" type="hinge" axis="0 0 1" range="-1.6144295580000001 1.6144295580000001"/><inertial pos="0.02200381568 -0.00049485095999999998 0.00053861122999999999" quat="1 0 0 0" mass="0.084576470000000001" diaginertia="4.9291288280000003e-05 5.9733381340000002e-05 3.9280838259999998e-05"/><geom name="right_wrist_yaw_link_collision" class="collision" type="mesh" pos="0 0 0" quat="1 0 0 0" mesh="right_wrist_yaw_link.STL"/><geom name="right_wrist_yaw_link_visual" class="visual" type="mesh" material="white" pos="0 0 0" quat="1 0 0 0" mesh="right_wrist_yaw_link.STL"/><body name="right_rubber_hand" pos="0.041500000000000002 -0.0030000000000000001 0" quat="1 0 0 0"><inertial pos="0.053613108079999999 0.0029590523999999999 0.00215413091" quat="1 0 0 0" mass="0.17000000000000001" diaginertia="0.00010099485234748001 0.00028135871571620998 0.00021894770413514"/><geom name="right_rubber_hand_visual" class="visual" type="mesh" material="white" pos="0 0 0" quat="1 0 0 0" mesh="right_rubber_hand.STL"/></body></body></body></body></body></body></body></body><body name="waist_support_link" pos="0.0039635 0 -0.053999999999999999" quat="1 0 0 0"><inertial pos="0 0 0" quat="1 0 0 0" mass="0.001" diaginertia="9.9999999999999995e-08 9.9999999999999995e-08 9.9999999999999995e-08"/><geom name="waist_support_link_collision" class="collision" type="mesh" pos="0 0 0" quat="1 0 0 0" mesh="waist_support_link.STL"/><geom name="waist_support_link_visual" class="visual" type="mesh" material="white" pos="0 0 0" quat="1 0 0 0" mesh="waist_support_link.STL"/></body></body></body></body></body></worldbody><actuator><motor name="left_hip_pitch_joint_ctrl" joint="left_hip_pitch_joint"/><motor name="left_hip_roll_joint_ctrl" joint="left_hip_roll_joint"/><motor name="left_hip_yaw_joint_ctrl" joint="left_hip_yaw_joint"/><motor name="left_knee_joint_ctrl" joint="left_knee_joint"/><motor name="left_ankle_pitch_joint_ctrl" joint="left_ankle_pitch_joint"/><motor name="left_ankle_roll_joint_ctrl" joint="left_ankle_roll_joint"/><motor name="right_hip_pitch_joint_ctrl" joint="right_hip_pitch_joint"/><motor name="right_hip_roll_joint_ctrl" joint="right_hip_roll_joint"/><motor name="right_hip_yaw_joint_ctrl" joint="right_hip_yaw_joint"/><motor name="right_knee_joint_ctrl" joint="right_knee_joint"/><motor name="right_ankle_pitch_joint_ctrl" joint="right_ankle_pitch_joint"/><motor name="right_ankle_roll_joint_ctrl" joint="right_ankle_roll_joint"/><motor name="waist_yaw_joint_ctrl" joint="waist_yaw_joint"/><motor name="waist_roll_joint_ctrl" joint="waist_roll_joint"/><motor name="waist_pitch_joint_ctrl" joint="waist_pitch_joint"/><motor name="left_shoulder_pitch_joint_ctrl" joint="left_shoulder_pitch_joint"/><motor name="left_shoulder_roll_joint_ctrl" joint="left_shoulder_roll_joint"/><motor name="left_shoulder_yaw_joint_ctrl" joint="left_shoulder_yaw_joint"/><motor name="left_elbow_joint_ctrl" joint="left_elbow_joint"/><motor name="left_wrist_roll_joint_ctrl" joint="left_wrist_roll_joint"/><motor name="left_wrist_pitch_joint_ctrl" joint="left_wrist_pitch_joint"/><motor name="left_wrist_yaw_joint_ctrl" joint="left_wrist_yaw_joint"/><motor name="right_shoulder_pitch_joint_ctrl" joint="right_shoulder_pitch_joint"/><motor name="right_shoulder_roll_joint_ctrl" joint="right_shoulder_roll_joint"/><motor name="right_shoulder_yaw_joint_ctrl" joint="right_shoulder_yaw_joint"/><motor name="right_elbow_joint_ctrl" joint="right_elbow_joint"/><motor name="right_wrist_roll_joint_ctrl" joint="right_wrist_roll_joint"/><motor name="right_wrist_pitch_joint_ctrl" joint="right_wrist_pitch_joint"/><motor name="right_wrist_yaw_joint_ctrl" joint="right_wrist_yaw_joint"/></actuator><contact><exclude body1="torso_link" body2="waist_support_link"/><exclude body1="right_shoulder_roll_link" body2="right_shoulder_yaw_link"/><exclude body1="torso_link" body2="right_shoulder_pitch_link"/><exclude body1="right_hip_yaw_link" body2="right_knee_link"/><exclude body1="right_hip_roll_link" body2="right_hip_yaw_link"/><exclude body1="right_wrist_roll_link" body2="right_wrist_pitch_link"/><exclude body1="right_knee_link" body2="right_ankle_pitch_link"/><exclude body1="left_wrist_pitch_link" body2="left_wrist_yaw_link"/><exclude body1="right_shoulder_yaw_link" body2="right_elbow_link"/><exclude body1="left_elbow_link" body2="left_wrist_roll_link"/><exclude body1="left_wrist_roll_link" body2="left_wrist_pitch_link"/><exclude body1="right_wrist_pitch_link" body2="right_wrist_yaw_link"/><exclude body1="right_elbow_link" body2="right_wrist_roll_link"/><exclude body1="right_hip_pitch_link" body2="right_hip_roll_link"/><exclude body1="left_shoulder_pitch_link" body2="left_shoulder_roll_link"/><exclude body1="left_hip_yaw_link" body2="left_knee_link"/><exclude body1="left_hip_roll_link" body2="left_hip_yaw_link"/><exclude body1="left_hip_pitch_link" body2="left_hip_roll_link"/><exclude body1="right_ankle_pitch_link" body2="right_ankle_roll_link"/><exclude body1="torso_link" body2="logo_link"/><exclude body1="left_shoulder_roll_link" body2="left_shoulder_yaw_link"/><exclude body1="left_shoulder_yaw_link" body2="left_elbow_link"/><exclude body1="right_shoulder_pitch_link" body2="right_shoulder_roll_link"/><exclude body1="torso_link" body2="left_shoulder_pitch_link"/><exclude body1="left_ankle_pitch_link" body2="left_ankle_roll_link"/><exclude body1="torso_link" body2="head_link"/><exclude body1="left_knee_link" body2="left_ankle_pitch_link"/></contact></mujoco>